{
 "cells": [
  {
   "cell_type": "code",
   "execution_count": 2,
   "metadata": {},
   "outputs": [],
   "source": [
    "from dask import delayed\n",
    "from dask.distributed import Client, LocalCluster\n",
    "\n",
    "cluster = LocalCluster()\n",
    "cluster.adapt(minimum=0, maximum=20)\n",
    "client = Client(cluster)"
   ]
  },
  {
   "cell_type": "code",
   "execution_count": 3,
   "metadata": {},
   "outputs": [
    {
     "data": {
      "text/plain": [
       "27403155622626313104"
      ]
     },
     "execution_count": 3,
     "metadata": {},
     "output_type": "execute_result"
    }
   ],
   "source": [
    "import asyncio\n",
    "\n",
    "#Execution of given example\n",
    "def func(x):\n",
    "    return delayed(x*x)\n",
    "\n",
    "out = func(5234802348).compute()\n",
    "out"
   ]
  },
  {
   "cell_type": "code",
   "execution_count": 7,
   "metadata": {},
   "outputs": [
    {
     "name": "stderr",
     "output_type": "stream",
     "text": [
      "distributed.scheduler - WARNING - Communication failed during replication: {'status': 'missing-data', 'keys': {\"('sum-193109010a71d9db0bbfa8df63539e52', 39, 28)\": ('tcp://127.0.0.1:56899',)}}\n",
      "distributed.scheduler - WARNING - Communication failed during replication: {'status': 'missing-data', 'keys': {\"('sum-193109010a71d9db0bbfa8df63539e52', 30, 11)\": ('tcp://127.0.0.1:56882',)}}\n",
      "distributed.scheduler - WARNING - Communication failed during replication: {'status': 'missing-data', 'keys': {\"('sum-193109010a71d9db0bbfa8df63539e52', 29, 24)\": ('tcp://127.0.0.1:56902',)}}\n",
      "distributed.utils - ERROR - \n",
      "Traceback (most recent call last):\n",
      "  File \"/Users/seena/opt/anaconda3/lib/python3.8/site-packages/distributed/utils.py\", line 655, in log_errors\n",
      "    yield\n",
      "  File \"/Users/seena/opt/anaconda3/lib/python3.8/site-packages/distributed/scheduler.py\", line 3515, in retire_workers\n",
      "    await self.replicate(\n",
      "  File \"/Users/seena/opt/anaconda3/lib/python3.8/site-packages/distributed/scheduler.py\", line 3274, in replicate\n",
      "    assert count > 0\n",
      "AssertionError\n",
      "distributed.core - ERROR - \n",
      "Traceback (most recent call last):\n",
      "  File \"/Users/seena/opt/anaconda3/lib/python3.8/site-packages/distributed/core.py\", line 528, in handle_comm\n",
      "    result = await result\n",
      "  File \"/Users/seena/opt/anaconda3/lib/python3.8/site-packages/distributed/scheduler.py\", line 3515, in retire_workers\n",
      "    await self.replicate(\n",
      "  File \"/Users/seena/opt/anaconda3/lib/python3.8/site-packages/distributed/scheduler.py\", line 3274, in replicate\n",
      "    assert count > 0\n",
      "AssertionError\n",
      "distributed.utils - ERROR - \n",
      "Traceback (most recent call last):\n",
      "  File \"/Users/seena/opt/anaconda3/lib/python3.8/site-packages/distributed/utils.py\", line 655, in log_errors\n",
      "    yield\n",
      "  File \"/Users/seena/opt/anaconda3/lib/python3.8/site-packages/distributed/deploy/adaptive.py\", line 187, in scale_down\n",
      "    await self.scheduler.retire_workers(\n",
      "  File \"/Users/seena/opt/anaconda3/lib/python3.8/site-packages/distributed/core.py\", line 812, in send_recv_from_rpc\n",
      "    result = await send_recv(comm=comm, op=key, **kwargs)\n",
      "  File \"/Users/seena/opt/anaconda3/lib/python3.8/site-packages/distributed/core.py\", line 682, in send_recv\n",
      "    raise exc.with_traceback(tb)\n",
      "  File \"/Users/seena/opt/anaconda3/lib/python3.8/site-packages/distributed/core.py\", line 528, in handle_comm\n",
      "    result = await result\n",
      "  File \"/Users/seena/opt/anaconda3/lib/python3.8/site-packages/distributed/scheduler.py\", line 3515, in retire_workers\n",
      "    await self.replicate(\n",
      "  File \"/Users/seena/opt/anaconda3/lib/python3.8/site-packages/distributed/scheduler.py\", line 3274, in replicate\n",
      "    assert count > 0\n",
      "AssertionError\n",
      "tornado.application - ERROR - Exception in callback functools.partial(<bound method IOLoop._discard_future_result of <zmq.eventloop.ioloop.ZMQIOLoop object at 0x7f841ff5b100>>, <Task finished name='Task-9107' coro=<AdaptiveCore.adapt() done, defined at /Users/seena/opt/anaconda3/lib/python3.8/site-packages/distributed/deploy/adaptive_core.py:179> exception=AssertionError()>)\n",
      "Traceback (most recent call last):\n",
      "  File \"/Users/seena/opt/anaconda3/lib/python3.8/site-packages/tornado/ioloop.py\", line 743, in _run_callback\n",
      "    ret = callback()\n",
      "  File \"/Users/seena/opt/anaconda3/lib/python3.8/site-packages/tornado/ioloop.py\", line 767, in _discard_future_result\n",
      "    future.result()\n",
      "  File \"/Users/seena/opt/anaconda3/lib/python3.8/site-packages/distributed/deploy/adaptive_core.py\", line 203, in adapt\n",
      "    await self.scale_down(**recommendations)\n",
      "  File \"/Users/seena/opt/anaconda3/lib/python3.8/site-packages/distributed/deploy/adaptive.py\", line 187, in scale_down\n",
      "    await self.scheduler.retire_workers(\n",
      "  File \"/Users/seena/opt/anaconda3/lib/python3.8/site-packages/distributed/core.py\", line 812, in send_recv_from_rpc\n",
      "    result = await send_recv(comm=comm, op=key, **kwargs)\n",
      "  File \"/Users/seena/opt/anaconda3/lib/python3.8/site-packages/distributed/core.py\", line 682, in send_recv\n",
      "    raise exc.with_traceback(tb)\n",
      "  File \"/Users/seena/opt/anaconda3/lib/python3.8/site-packages/distributed/core.py\", line 528, in handle_comm\n",
      "    result = await result\n",
      "  File \"/Users/seena/opt/anaconda3/lib/python3.8/site-packages/distributed/scheduler.py\", line 3515, in retire_workers\n",
      "    await self.replicate(\n",
      "  File \"/Users/seena/opt/anaconda3/lib/python3.8/site-packages/distributed/scheduler.py\", line 3274, in replicate\n",
      "    assert count > 0\n",
      "AssertionError\n",
      "distributed.utils - ERROR - \n",
      "Traceback (most recent call last):\n",
      "  File \"/Users/seena/opt/anaconda3/lib/python3.8/site-packages/distributed/utils.py\", line 655, in log_errors\n",
      "    yield\n",
      "  File \"/Users/seena/opt/anaconda3/lib/python3.8/site-packages/distributed/scheduler.py\", line 3515, in retire_workers\n",
      "    await self.replicate(\n",
      "  File \"/Users/seena/opt/anaconda3/lib/python3.8/site-packages/distributed/scheduler.py\", line 3274, in replicate\n",
      "    assert count > 0\n",
      "AssertionError\n",
      "distributed.core - ERROR - \n",
      "Traceback (most recent call last):\n",
      "  File \"/Users/seena/opt/anaconda3/lib/python3.8/site-packages/distributed/core.py\", line 528, in handle_comm\n",
      "    result = await result\n",
      "  File \"/Users/seena/opt/anaconda3/lib/python3.8/site-packages/distributed/scheduler.py\", line 3515, in retire_workers\n",
      "    await self.replicate(\n",
      "  File \"/Users/seena/opt/anaconda3/lib/python3.8/site-packages/distributed/scheduler.py\", line 3274, in replicate\n",
      "    assert count > 0\n",
      "AssertionError\n",
      "distributed.utils - ERROR - \n",
      "Traceback (most recent call last):\n",
      "  File \"/Users/seena/opt/anaconda3/lib/python3.8/site-packages/distributed/utils.py\", line 655, in log_errors\n",
      "    yield\n",
      "  File \"/Users/seena/opt/anaconda3/lib/python3.8/site-packages/distributed/deploy/adaptive.py\", line 187, in scale_down\n",
      "    await self.scheduler.retire_workers(\n",
      "  File \"/Users/seena/opt/anaconda3/lib/python3.8/site-packages/distributed/core.py\", line 812, in send_recv_from_rpc\n",
      "    result = await send_recv(comm=comm, op=key, **kwargs)\n",
      "  File \"/Users/seena/opt/anaconda3/lib/python3.8/site-packages/distributed/core.py\", line 682, in send_recv\n",
      "    raise exc.with_traceback(tb)\n",
      "  File \"/Users/seena/opt/anaconda3/lib/python3.8/site-packages/distributed/core.py\", line 528, in handle_comm\n",
      "    result = await result\n",
      "  File \"/Users/seena/opt/anaconda3/lib/python3.8/site-packages/distributed/scheduler.py\", line 3515, in retire_workers\n",
      "    await self.replicate(\n",
      "  File \"/Users/seena/opt/anaconda3/lib/python3.8/site-packages/distributed/scheduler.py\", line 3274, in replicate\n",
      "    assert count > 0\n",
      "AssertionError\n",
      "tornado.application - ERROR - Exception in callback functools.partial(<bound method IOLoop._discard_future_result of <zmq.eventloop.ioloop.ZMQIOLoop object at 0x7f841ff5b100>>, <Task finished name='Task-9652' coro=<AdaptiveCore.adapt() done, defined at /Users/seena/opt/anaconda3/lib/python3.8/site-packages/distributed/deploy/adaptive_core.py:179> exception=AssertionError()>)\n",
      "Traceback (most recent call last):\n",
      "  File \"/Users/seena/opt/anaconda3/lib/python3.8/site-packages/tornado/ioloop.py\", line 743, in _run_callback\n",
      "    ret = callback()\n",
      "  File \"/Users/seena/opt/anaconda3/lib/python3.8/site-packages/tornado/ioloop.py\", line 767, in _discard_future_result\n",
      "    future.result()\n",
      "  File \"/Users/seena/opt/anaconda3/lib/python3.8/site-packages/distributed/deploy/adaptive_core.py\", line 203, in adapt\n",
      "    await self.scale_down(**recommendations)\n",
      "  File \"/Users/seena/opt/anaconda3/lib/python3.8/site-packages/distributed/deploy/adaptive.py\", line 187, in scale_down\n",
      "    await self.scheduler.retire_workers(\n",
      "  File \"/Users/seena/opt/anaconda3/lib/python3.8/site-packages/distributed/core.py\", line 812, in send_recv_from_rpc\n",
      "    result = await send_recv(comm=comm, op=key, **kwargs)\n",
      "  File \"/Users/seena/opt/anaconda3/lib/python3.8/site-packages/distributed/core.py\", line 682, in send_recv\n",
      "    raise exc.with_traceback(tb)\n",
      "  File \"/Users/seena/opt/anaconda3/lib/python3.8/site-packages/distributed/core.py\", line 528, in handle_comm\n",
      "    result = await result\n",
      "  File \"/Users/seena/opt/anaconda3/lib/python3.8/site-packages/distributed/scheduler.py\", line 3515, in retire_workers\n",
      "    await self.replicate(\n",
      "  File \"/Users/seena/opt/anaconda3/lib/python3.8/site-packages/distributed/scheduler.py\", line 3274, in replicate\n",
      "    assert count > 0\n",
      "AssertionError\n"
     ]
    },
    {
     "name": "stderr",
     "output_type": "stream",
     "text": [
      "distributed.utils - ERROR - \n",
      "Traceback (most recent call last):\n",
      "  File \"/Users/seena/opt/anaconda3/lib/python3.8/site-packages/distributed/utils.py\", line 655, in log_errors\n",
      "    yield\n",
      "  File \"/Users/seena/opt/anaconda3/lib/python3.8/site-packages/distributed/scheduler.py\", line 3515, in retire_workers\n",
      "    await self.replicate(\n",
      "  File \"/Users/seena/opt/anaconda3/lib/python3.8/site-packages/distributed/scheduler.py\", line 3274, in replicate\n",
      "    assert count > 0\n",
      "AssertionError\n",
      "distributed.core - ERROR - \n",
      "Traceback (most recent call last):\n",
      "  File \"/Users/seena/opt/anaconda3/lib/python3.8/site-packages/distributed/core.py\", line 528, in handle_comm\n",
      "    result = await result\n",
      "  File \"/Users/seena/opt/anaconda3/lib/python3.8/site-packages/distributed/scheduler.py\", line 3515, in retire_workers\n",
      "    await self.replicate(\n",
      "  File \"/Users/seena/opt/anaconda3/lib/python3.8/site-packages/distributed/scheduler.py\", line 3274, in replicate\n",
      "    assert count > 0\n",
      "AssertionError\n",
      "distributed.utils - ERROR - \n",
      "Traceback (most recent call last):\n",
      "  File \"/Users/seena/opt/anaconda3/lib/python3.8/site-packages/distributed/utils.py\", line 655, in log_errors\n",
      "    yield\n",
      "  File \"/Users/seena/opt/anaconda3/lib/python3.8/site-packages/distributed/deploy/adaptive.py\", line 187, in scale_down\n",
      "    await self.scheduler.retire_workers(\n",
      "  File \"/Users/seena/opt/anaconda3/lib/python3.8/site-packages/distributed/core.py\", line 812, in send_recv_from_rpc\n",
      "    result = await send_recv(comm=comm, op=key, **kwargs)\n",
      "  File \"/Users/seena/opt/anaconda3/lib/python3.8/site-packages/distributed/core.py\", line 682, in send_recv\n",
      "    raise exc.with_traceback(tb)\n",
      "  File \"/Users/seena/opt/anaconda3/lib/python3.8/site-packages/distributed/core.py\", line 528, in handle_comm\n",
      "    result = await result\n",
      "  File \"/Users/seena/opt/anaconda3/lib/python3.8/site-packages/distributed/scheduler.py\", line 3515, in retire_workers\n",
      "    await self.replicate(\n",
      "  File \"/Users/seena/opt/anaconda3/lib/python3.8/site-packages/distributed/scheduler.py\", line 3274, in replicate\n",
      "    assert count > 0\n",
      "AssertionError\n",
      "tornado.application - ERROR - Exception in callback functools.partial(<bound method IOLoop._discard_future_result of <zmq.eventloop.ioloop.ZMQIOLoop object at 0x7f841ff5b100>>, <Task finished name='Task-12382' coro=<AdaptiveCore.adapt() done, defined at /Users/seena/opt/anaconda3/lib/python3.8/site-packages/distributed/deploy/adaptive_core.py:179> exception=AssertionError()>)\n",
      "Traceback (most recent call last):\n",
      "  File \"/Users/seena/opt/anaconda3/lib/python3.8/site-packages/tornado/ioloop.py\", line 743, in _run_callback\n",
      "    ret = callback()\n",
      "  File \"/Users/seena/opt/anaconda3/lib/python3.8/site-packages/tornado/ioloop.py\", line 767, in _discard_future_result\n",
      "    future.result()\n",
      "  File \"/Users/seena/opt/anaconda3/lib/python3.8/site-packages/distributed/deploy/adaptive_core.py\", line 203, in adapt\n",
      "    await self.scale_down(**recommendations)\n",
      "  File \"/Users/seena/opt/anaconda3/lib/python3.8/site-packages/distributed/deploy/adaptive.py\", line 187, in scale_down\n",
      "    await self.scheduler.retire_workers(\n",
      "  File \"/Users/seena/opt/anaconda3/lib/python3.8/site-packages/distributed/core.py\", line 812, in send_recv_from_rpc\n",
      "    result = await send_recv(comm=comm, op=key, **kwargs)\n",
      "  File \"/Users/seena/opt/anaconda3/lib/python3.8/site-packages/distributed/core.py\", line 682, in send_recv\n",
      "    raise exc.with_traceback(tb)\n",
      "  File \"/Users/seena/opt/anaconda3/lib/python3.8/site-packages/distributed/core.py\", line 528, in handle_comm\n",
      "    result = await result\n",
      "  File \"/Users/seena/opt/anaconda3/lib/python3.8/site-packages/distributed/scheduler.py\", line 3515, in retire_workers\n",
      "    await self.replicate(\n",
      "  File \"/Users/seena/opt/anaconda3/lib/python3.8/site-packages/distributed/scheduler.py\", line 3274, in replicate\n",
      "    assert count > 0\n",
      "AssertionError\n"
     ]
    },
    {
     "data": {
      "text/plain": [
       "2749239453.487661"
      ]
     },
     "execution_count": 7,
     "metadata": {},
     "output_type": "execute_result"
    }
   ],
   "source": [
    "#Load-testing function:\n",
    "import dask.array as da\n",
    "def loadTest():\n",
    "    x = da.random.random((40000, 40000), chunks=(1000,1000))\n",
    "    y = da.exp(x).sum()\n",
    "    return y\n",
    "\n",
    "out = loadTest().compute()\n",
    "out"
   ]
  }
 ],
 "metadata": {
  "kernelspec": {
   "display_name": "Python 3",
   "language": "python",
   "name": "python3"
  },
  "language_info": {
   "codemirror_mode": {
    "name": "ipython",
    "version": 3
   },
   "file_extension": ".py",
   "mimetype": "text/x-python",
   "name": "python",
   "nbconvert_exporter": "python",
   "pygments_lexer": "ipython3",
   "version": "3.8.5"
  }
 },
 "nbformat": 4,
 "nbformat_minor": 4
}
